Workbook

Sheet ReadMe
A1: Author: | B1: Linh Le
A2: Project: | B2: WEB CONDUIT – REALWORLD
A3: Version: | B3: v1.0
A4: Version Date:
A5: Copyright:
A8: Mỗi version sẽ có 1 bộ test case , requirement matrix, các test cases chạy trong từng Sprint của version đó và thông tin chạy regression của version đó
A9: Sang version khác sẽ đóng file excel này lại và clone ra bản mới cho version tiếp theo
A10: PM có thể biết được ở mỗi sprint quyết định chạy những test cases nào, nếu release gấp ví dụ sau sprint 3 chưa chạy regression nhưng cần release gấp cho khách hàng -> nếu xảy ra lỗi thì cũng trace back lại được là lỗi đó ở đâu, do thiếu test cases hay do không chạy test case trong sprint đó -> nếu thiếu thì cập nhập nhưng nếu do không chọn chạy test case trong sprint đó thì độ coverage chưa cao, cần cải thiện khi quyết định chọn test cases nào sẽ chạy
A11: Thường kết thúc các sprint trong version thì sẽ chạy regression cho toàn bộ test case, kết quả Test Execution và Pass rate sẽ là 2 điều kiện để quyết đinh xem có release cho khách hàng không (xem sheet regression Testing)
A17: Legend

Sheet Requirement Matrix
A1: ID | B1: Tên Yêu cầu (Requirement Name) | C1: Mô tả yêu cầu (Requirement Description) | D1: Loại Yêu cầu | E1: Nguồn tham chiếu | F1: Mức độ ưu tiên | G1: Rủi ro tiềm ẩn (Risks) | H1: Trạng thái | I1: Người chịu trách nhiệm | J1: Tiêu chí chấp thuận (Acceptance Criteria) | K1: Test Case ID
A2: REQ-01 | B2: Đăng ký tài khoản | C2: Là một khách (Guest), tôi muốn đăng ký một tài khoản để có thể trở thành thành viên. | D2: Chức năng | E2: Business Rules | F2: Cao | G2: Bảo mật | H2: Hoàn thành | I2: Product Manager | J2: Tạo user mới trong DB và trả về Token | K2: TC01.1, TC01.2, TC01.3
A3: REQ-02 | B3: Đăng nhập hệ thống | C3: Là một người dùng (User), tôi muốn đăng nhập bằng Email và Password để đăng nhập vào hệ thống | D3: Chức năng | E3: Business Rules | F3: Cao | G3: Bảo mật | H3: Hoàn thành | I3: Product Manager | J3: Đăng nhập thành công và được điều hướng qua trang chủ Lưu Token để giữ session đăng nhập | K3: TC02.1, TC02.2, TC02.3
A4: REQ-03 | B4: Tạo bài viết mới | C4: Là một tác giả, tôi muốn tạo và xuất bản một bài viết mới để chia sẻ kiến thức | D4: Chức năng | E4: Business Rules | F4: Cao | G4: Logic luồng hiển thị | H4: Hoàn thành | I4: Product Manager | J4: Bài viết lưu DB, tự động index lên trang Global Feed, Your Feed, và trang My Articles trong User Profile | K4: TC03.1, TC03.2, TC03.3, TC03.4, TC03.5
A5: REQ-04 | B5: Đọc bài viết | C5: Là một người dùng, tôi muốn đọc chi tiết một bài viết để tiếp thu thông tin. | D5: Chức năng | E5: Business Rules | F5: Trung bình | G5: Lỗi render nội dung Markdown (Gây vỡ Layout, tràn chữ trên Mobile, hoặc hiển thị sai định dạng HTML) | H5: Hoàn thành | I5: Product Manager | J5: Khi nhấn vào xem bài viết hoặc nhấn chữ View More, hệ thống sẽ điều hướng qua trang Xem chi tiết bài viết. Văn bản Markdown render chính xác | K5: TC04.1
A6: REQ-05 | B6: Cập nhật bài viết | C6: Là một tác giả, tôi muốn chỉnh sửa bài viết của mình để cập nhật thông tin mới. | D6: Chức năng | E6: Business Rules | F6: Cao | G6: Xung đột State | H6: Hoàn thành | I6: Product Manager | J6: Thời gian updated_at thay đổi, nội dung mới hiển thị trên các trang tương ứng | K6: TC05.1,TC05.2
A7: REQ-06 | B7: Xóa bài viết | C7: Là một tác giả, tôi muốn xóa bài viết cũ của mình để nó không còn hiển thị. | D7: Chức năng | E7: Business Rules | F7: Trung bình | G7: Lỗi Cache | H7: Hoàn thành | I7: Product Manager | J7: Bài viết bị xóa khỏi DB và trên các trang hiển thị bài viết thông báo xóa Thành công với user | K7: TC06.1
A8: REQ-07 | B8: Bình luận bài viết | C8: Là một người dùng, tôi muốn viết bình luận vào bài viết của người khác và chính bài viết của mình | D8: Chức năng | E8: Business Rules | F8: Trung bình | G8: Không | H8: Hoàn thành | I8: Product Manager | J8: Người dùng có thể bình luận vào bài viết của chính mình và của người khác Bình luận mới nhất sẽ trôi xuống cuối danh sách | K8: TC07.1, TC07.2
A9: REQ-08 | B9: Yêu thích bài viết và theo dõi tác giả | C9: Là một người dùng, tôi muốn thả tim bài viết để khích lệ tác giả hoặc thả tym cho chính bài viết của mình | D9: Chức năng | E9: Business Rules | F9: Trung bình | G9: Xung đột Component | H9: Hoàn thành | I9: Product Manager | J9: Trái tim chuyển đổi trạng thái lập tức (Sync) | K9: TC08.1
A10: REQ-09 | B10: Theo dõi tác giả bài viết | C10: Là một người dùng, tôi muốn theo dõi tác giả mà tôi yêu thích để đọc nhiều bài viết hay từ họ | D10: Chức năng | E10: Business Rules | F10: Trung bình | G10: Không | H10: Hoàn thành | I10: Product Manager | J10: Sau khi nhấn theo dõi, thì trang Your Feed chỉ hiển thị các bài viết của các tác giả đã theo dõi | K10: TC09.1
A11: REQ-10 | B11: Xem Hồ sơ cá nhân | C11: Là một người dùng, tôi muốn xem trang Profile để theo dõi bài mình đã viết/thích. | D11: Chức năng | E11: Business Rules | F11: Cao | G11: Không | H11: Hoàn thành | I11: Product Manager | J11: Tab Favorited lọc chính xác bài viết mình đã yêu thích, bài viết yêu thích gần nhất sẽ hiển thị lên đầu Tab My Articles lọc chính xác bài viết người dùng đã tạo, bài viết mới nhất sẽ hiển thị lên đầu | K11: TC10.1, TC10.2

Sheet Test Case List
A1: Scenario ID | B1: Scenario | C1: Test Case ID | D1: Test Case Name | E1: Test Case Description | F1: Expected Result | G1: Status | H1: Owner | I1: Approver(s) | J1: Comments | K1: Business Requirement(s) | L1: Module | M1: Priority | N1: Test type
A2: TS1 | B2: Đăng ký | C2: TC01.1 | D2: Đăng ký hợp lệ | E2: B1: Điền đúng email hợp lệ B2: Điền đúng password theo yêu cầu B3: Điền Tên của người dùng B4: Nhấn nút đăng ký | F2: Đăng ký thành công kèm thông báo | G2: Approved | H2: Linh Le | I2: QA Manager | J2: Automated | K2: REQ-01 | L2: Auth | M2: High | N2: Functional Testing
A3: TS1 | B3: Đăng ký | C3: TC01.2 | D3: Đăng ký email trùng với user đã tồn tại trong hệ thống | E3: B1: Tạo sẵn 1 user với email trong hệ thống B2: Đăng ký thêm với cùng email đó B3: Nhấn nút đăng ký | F3: Hệ thống báo lỗi email đã được sử dụng | G3: Approved | H3: Linh Le | I3: QA Manager | J3: Manual | K3: REQ-01 | L3: Auth | M3: High | N3: Functional Testing
A4: TS1 | B4: Đăng ký | C4: TC01.3 | D4: Đăng ký bỏ trống trường email hoặc trường password | E4: B1: Điền Tên người dùng B2: bỏ trống email hoặc password B3: nhấn nút đăng ký | F4: Hệ thống báo lỗi cần nhập email/password | G4: Approved | H4: Linh Le | I4: QA Manager | J4: Manual | K4: REQ-01 | L4: Auth | M4: High | N4: Functional Testing
A5: TS2 | B5: Đăng nhập | C5: TC02.1 | D5: Đăng nhập hợp lệ | E5: B1: Điền thông tin email B2: Điền thông tin password B3: Nhấn nút đăng nhập | F5: Hệ thống thông báo đăng nhập thành công và điều hướng đến trang chủ | G5: Approved | H5: Linh Le | I5: QA Manager | J5: Automated | K5: REQ-02 | L5: Auth | M5: High | N5: Functional Testing
A6: TS2 | B6: Đăng nhập | C6: TC02.2 | D6: Đăng nhập sai pass | E6: B1: Điền thông tin email B2: Điền thông tin password sai B3: Nhấn nút đăng nhập | F6: Hệ thống báo lỗi mật khẩu không đúng | G6: Approved | H6: Linh Le | I6: QA Manager | J6: Manual | K6: REQ-02 | L6: Auth | M6: High | N6: Functional Testing
A7: TS2 | B7: Đăng nhập | C7: TC02.3 | D7: Đăng nhập sai email | E7: B1: Điền thông tin email sai B2: Điền thông tin password đúng B3: Nhấn nút đăng nhập | F7: Hệ thống báo lỗi email không đúng | G7: Approved | H7: Linh Le | I7: QA Manager | J7: Manual | K7: REQ-02 | L7: Auth | M7: High | N7: Functional Testing
A8: TS3 | B8: Tạo bài viết | C8: TC03.1 | D8: Kiểm tra UI form tạo bài viết có đủ các trường thông tin | E8: B1: Nhấn nút New Article B2: Xác nhận đủ các field (Title, About, Body, Tags) | F8: Có đủ các field (Title, About, Body, Tags) | G8: Approved | H8: Linh Le | I8: QA Manager | J8: Manual | K8: REQ-03 | L8: Article | M8: High | N8: Functional Testing
A9: TS3 | B9: Tạo bài viết | C9: TC03.2 | D9: Kiểm tra khi nhấn nút publish article nhưng bỏ trống các trường bắt buộc | E9: B1: Nhấn nút New Article B2: bỏ trống 1 trong các fields (Title, About, Body) B3: nhấn nút publish article | F9: Hệ thống báo lỗi cần điền các fields (Title, About, Body) | G9: Approved | H9: Linh Le | I9: QA Manager | J9: Manual | K9: REQ-03 | L9: Article | M9: High | N9: Functional Testing
A10: TS3 | B10: Tạo bài viết | C10: TC03.3 | D10: Kiểm tra tạo bài viết với Title đã tồn tại | E10: B1: Nhấn nút New Article B2: điền đủ các fields (Title, About, Body, Tags) B3: nhấn nút publish article B4: Nhấn nút New Article B5: điền đủ các fields (Title, About, Body, Tags) nhưng với title name trùng với B2 B6: nhấn nút publish article | F10: Hệ thống cho phép tạo thành công bình thường | G10: Approved | H10: Linh Le | I10: QA Manager | J10: Automated | K10: REQ-03 | L10: Article | M10: High | N10: Functional Testing
A11: TS3 | B11: Tạo bài viết | C11: TC03.4 | D11: Kiểm tra số lượng ký tự giới hạn trong các fields | E11: Boundary testing | F11: Giới hạn text | G11: Approved | H11: Linh Le | I11: QA Manager | J11: Manual | K11: REQ-03 | L11: Article | M11: High | N11: Functional Testing
A12: TS3 | B12: Tạo bài viết | C12: TC03.5 | D12: Kiểm tra bài viết hiển thị trên Global Feed, My Article trong User Profile sau khi tạo | E12: B1: tạo bài viết B2: truy cập các trang Global Feed, My Article trong User Profile và kiểm tra bài viết | F12: Bài viết mới tạo hiện thị trên đầu ở các trang Global Feed, My Article trong User Profile | G12: Approved | H12: Linh Le | I12: QA Manager | J12: Manual | K12: REQ-03 | L12: Article | M12: High | N12: Functional Testing
... A22: TS10 | B22: Hồ sơ cá nhân | C22: TC10.2 | D22: Kiểm tra tab Favorited Articles | E22: B1: Truy cập trang User profile B2: kiểm tra tab Favorited Articles | F22: hiển thị bài viết mà mình đã thả tym, bài mới nhất sẽ hiển thị lên đầu | G22: Approved | H22: Linh Le | I22: QA Manager | J22: Manual | K22: REQ-10 | L22: Profile | M22: High | N22: Functional Testing
A48: Insert lines above here only | D48: Insert lines above here only | G48: Insert lines above here only | K48: Insert lines above here only
A50: Warning: Be careful adding/removing rows in the following section - these values are used for data validation
A51: Test Case Status | D51: Module | F51: Test Type
A52: Not Started | D52: Auth | F52: Functional Testing
A53: In Progress | D53: Article | F53: Integration Testing
A54: Draft | D54: Social | F54: UI Testing
A55: Pending Approval | D55: Profile | F55: Performance Testing
A56: Approved | F56: Security Testing
F59: Current Sprint
F60: 3
A62: Test Case Owner
A63: Linh Le
D66: Priority
D67: High
D68: Medium
D69: Low

Sheet Test Case Coverage Plan
D1: Include in Test Iteration:
A2: Test Case ID | B2: Test Case Name | C2: Module | D2: Sprint 1 (Auth) | E2: Sprint 2 (Article) | F2: Sprint 3 (Social&Profile) | G2: Planned Lead Tester | H2: Comments
A3: ='Test Case List'!C2 -> TC01.1 | B3: ='Test Case List'!D2 -> Đăng ký hợp lệ | C3: ='Test Case List'!L2 -> Auth | D3: Yes | E3: No | F3: Yes | G3: Linh Le
A4: ='Test Case List'!C3 -> TC01.2 | B4: ='Test Case List'!D3 -> Đăng ký email trùng với user đã tồn tại trong hệ thống | C4: ='Test Case List'!L3 -> Auth | D4: Yes | E4: No | F4: No | G4: Linh Le
A5: ='Test Case List'!C4 -> TC01.3 | B5: ='Test Case List'!D4 -> Đăng ký bỏ trống trường email hoặc trường password | C5: ='Test Case List'!L4 -> Auth | D5: Yes | E5: No | F5: No | G5: Linh Le
A6: ='Test Case List'!C5 -> TC02.1 | B6: ='Test Case List'!D5 -> Đăng nhập hợp lệ | C6: ='Test Case List'!L5 -> Auth | D6: Yes | E6: Yes | F6: Yes | G6: Linh Le
A7: ='Test Case List'!C6 -> TC02.2 | B7: ='Test Case List'!D6 -> Đăng nhập sai pass | C7: ='Test Case List'!L6 -> Auth | D7: Yes | E7: Yes | F7: No | G7: Linh Le
A8: ='Test Case List'!C7 -> TC02.3 | B8: ='Test Case List'!D7 -> Đăng nhập sai email | C8: ='Test Case List'!L7 -> Auth | D8: Yes | E8: Yes | F8: No | G8: Linh Le
A9: ='Test Case List'!C8 -> TC03.1 | B9: ='Test Case List'!D8 -> Kiểm tra UI form tạo bài viết có đủ các trường thông tin | C9: ='Test Case List'!L8 -> Article | D9: No | E9: Yes | F9: Yes | G9: Linh Le
A10: ='Test Case List'!C9 -> TC03.2 | B10: ='Test Case List'!D9 -> Kiểm tra khi nhấn nút publish article nhưng bỏ trống các trường bắt buộc | C10: ='Test Case List'!L9 -> Article | D10: No | E10: Yes | F10: Yes | G10: Linh Le
A11: ='Test Case List'!C10 -> TC03.3 | B11: ='Test Case List'!D10 -> Kiểm tra tạo bài viết với Title đã tồn tại | C11: ='Test Case List'!L10 -> Article | D11: No | E11: Yes | F11: Yes | G11: Linh Le
A12: ='Test Case List'!C11 -> TC03.4 | B12: ='Test Case List'!D11 -> Kiểm tra số lượng ký tự giới hạn trong các fields | C12: ='Test Case List'!L11 -> Article | D12: No | E12: Yes | F12: Yes | G12: Linh Le
A13: ='Test Case List'!C12 -> TC03.5 | B13: ='Test Case List'!D12 -> Kiểm tra bài viết hiển thị trên Global Feed, My Article trong User Profile sau khi tạo | C13: ='Test Case List'!L12 -> Article | D13: No | E13: Yes | F13: Yes | G13: Linh Le
A14: ='Test Case List'!C13 -> TC04.1 | B14: ='Test Case List'!D13 -> Đọc chi tiết bài viết | C14: ='Test Case List'!L13 -> Article | D14: No | E14: Yes | F14: Yes | G14: Linh Le
... A23: ='Test Case List'!C22 -> TC10.2 | B23: ='Test Case List'!D22 -> Kiểm tra tab Favorited Articles | C23: ='Test Case List'!L22 -> Profile | D23: No | E23: No | F23: Yes | G23: Linh Le
A82: Insert Lines Above Here Only | D82: Insert Lines Above Here Only
A84: Warning: Be careful adding/removing rows in the following section - these values are used for data validation
A85: Include in Test Iteration
A86: Pending
A87: Yes
A88: No
A94: Planned Tester
A95: Linh Le
A96: Tester 2

Sheet Sprint 1
A1: Test Case ID | B1: Test Case Name | C1: Module | D1: In This Test Iteration? | E1: Tester | F1: Status | G1: Defects Identified | H1: Blocking Defect ID(s) | I1: Comments
A2: ='Test Case List'!C2 -> TC01.1 | B2: ='Test Case List'!D2 -> Đăng ký hợp lệ | C2: =Table2[[#This Row],[Module]] -> Auth | D2: =VLOOKUP(A2,'Test Case Coverage Plan'!A3:F27,4,FALSE) -> Yes | E2: Linh Le | F2: Run - Passed
A3: ='Test Case List'!C3 -> TC01.2 | B3: ='Test Case List'!D3 -> Đăng ký email trùng với user đã tồn tại trong hệ thống | C3: =Table2[[#This Row],[Module]] -> Auth | D3: =VLOOKUP(A3,'Test Case Coverage Plan'!A4:F28,4,FALSE) -> Yes | E3: Linh Le | F3: Run - Passed
A4: ='Test Case List'!C4 -> TC01.3 | B4: ='Test Case List'!D4 -> Đăng ký bỏ trống trường email hoặc trường password | C4: =Table2[[#This Row],[Module]] -> Auth | D4: =VLOOKUP(A4,'Test Case Coverage Plan'!A5:F29,4,FALSE) -> Yes | E4: Linh Le | F4: Run - Passed
A5: ='Test Case List'!C5 -> TC02.1 | B5: ='Test Case List'!D5 -> Đăng nhập hợp lệ | C5: =Table2[[#This Row],[Module]] -> Auth | D5: =VLOOKUP(A5,'Test Case Coverage Plan'!A6:F30,4,FALSE) -> Yes | E5: Linh Le | F5: Run - Passed
A6: ='Test Case List'!C6 -> TC02.2 | B6: ='Test Case List'!D6 -> Đăng nhập sai pass | C6: =Table2[[#This Row],[Module]] -> Auth | D6: =VLOOKUP(A6,'Test Case Coverage Plan'!A7:F31,4,FALSE) -> Yes | E6: Linh Le | F6: Run - Passed
A7: ='Test Case List'!C7 -> TC02.3 | B7: ='Test Case List'!D7 -> Đăng nhập sai email | C7: =Table2[[#This Row],[Module]] -> Auth | D7: =VLOOKUP(A7,'Test Case Coverage Plan'!A8:F32,4,FALSE) -> Yes | E7: Linh Le | F7: Run - Passed
A8: ='Test Case List'!C8 -> TC03.1 | B8: ='Test Case List'!D8 -> Kiểm tra UI form tạo bài viết có đủ các trường thông tin | C8: =Table2[[#This Row],[Module]] -> Article | D8: =VLOOKUP(A8,'Test Case Coverage Plan'!A9:F33,4,FALSE) -> No | E8: Linh Le | F8: Blocked
A9: ='Test Case List'!C9 -> TC03.2 | B9: ='Test Case List'!D9 -> Kiểm tra khi nhấn nút publish article nhưng bỏ trống các trường bắt buộc | C9: =Table2[[#This Row],[Module]] -> Article | D9: =VLOOKUP(A9,'Test Case Coverage Plan'!A10:F34,4,FALSE) -> No | E9: Linh Le | F9: Blocked
A10: ='Test Case List'!C10 -> TC03.3 | B10: ='Test Case List'!D10 -> Kiểm tra tạo bài viết với Title đã tồn tại | C10: =Table2[[#This Row],[Module]] -> Article | D10: =VLOOKUP(A10,'Test Case Coverage Plan'!A11:F35,4,FALSE) -> No | E10: Linh Le | F10: Blocked
A11: ='Test Case List'!C11 -> TC03.4 | B11: ='Test Case List'!D11 -> Kiểm tra số lượng ký tự giới hạn trong các fields | C11: =Table2[[#This Row],[Module]] -> Article | D11: =VLOOKUP(A11,'Test Case Coverage Plan'!A12:F36,4,FALSE) -> No | E11: Linh Le | F11: Blocked
A12: ='Test Case List'!C12 -> TC03.5 | B12: ='Test Case List'!D12 -> Kiểm tra bài viết hiển thị trên Global Feed, My Article trong User Profile sau khi tạo | C12: =Table2[[#This Row],[Module]] -> Article | D12: =VLOOKUP(A12,'Test Case Coverage Plan'!A13:F37,4,FALSE) -> No | E12: Linh Le | F12: Blocked
A13: ='Test Case List'!C13 -> TC04.1 | B13: ='Test Case List'!D13 -> Đọc chi tiết bài viết | C13: =Table2[[#This Row],[Module]] -> Article | D13: =VLOOKUP(A13,'Test Case Coverage Plan'!A14:F38,4,FALSE) -> No | E13: Linh Le | F13: Blocked
... A22: ='Test Case List'!C22 -> TC10.2 | B22: ='Test Case List'!D22 -> Kiểm tra tab Favorited Articles | C22: =Table2[[#This Row],[Module]] -> Profile | D22: =VLOOKUP(A22,'Test Case Coverage Plan'!A23:F47,4,FALSE) -> No | E22: Linh Le | F22: Blocked
A45: Insert Rows Only Above Here | E45: Insert Rows Only Above Here
A47: Warning: Be careful adding/removing rows in the following section - these values are used for data validation
A48: Tester | E48: Test Case Status | H48: Test Iteration Name
A49: Linh Le | E49: N/A | H49: Sprint 1 (Auth)
A50: Tester 2 | E50: Not Run
E51: Blocked
E52: In Progress
E53: Run - Passed
E54: Run - Failed

Sheet Sprint 2
A1: Test Case ID | B1: Test Case Name | C1: Module | D1: In This Test Iteration? | E1: Tester | F1: Status | G1: Defects Identified | H1: Blocking Defect ID | I1: Comments
A2: ='Test Case List'!C2 -> TC01.1 | B2: ='Test Case List'!D2 -> Đăng ký hợp lệ | C2: =Table2[[#This Row],[Module]] -> Auth | D2: =VLOOKUP(A2,'Test Case Coverage Plan'!A3:F27,5,FALSE) -> No | E2: Linh Le | F2: Not Run
A3: ='Test Case List'!C3 -> TC01.2 | B3: ='Test Case List'!D3 -> Đăng ký email trùng với user đã tồn tại trong hệ thống | C3: =Table2[[#This Row],[Module]] -> Auth | D3: =VLOOKUP(A3,'Test Case Coverage Plan'!A4:F28,5,FALSE) -> No | E3: Linh Le | F3: Not Run
A4: ='Test Case List'!C4 -> TC01.3 | B4: ='Test Case List'!D4 -> Đăng ký bỏ trống trường email hoặc trường password | C4: =Table2[[#This Row],[Module]] -> Auth | D4: =VLOOKUP(A4,'Test Case Coverage Plan'!A5:F29,5,FALSE) -> No | E4: Linh Le | F4: Not Run
A5: ='Test Case List'!C5 -> TC02.1 | B5: ='Test Case List'!D5 -> Đăng nhập hợp lệ | C5: =Table2[[#This Row],[Module]] -> Auth | D5: =VLOOKUP(A5,'Test Case Coverage Plan'!A6:F30,5,FALSE) -> Yes | E5: Linh Le | F5: Run - Passed
A6: ='Test Case List'!C6 -> TC02.2 | B6: ='Test Case List'!D6 -> Đăng nhập sai pass | C6: =Table2[[#This Row],[Module]] -> Auth | D6: =VLOOKUP(A6,'Test Case Coverage Plan'!A7:F31,5,FALSE) -> Yes | E6: Linh Le | F6: Run - Passed
A7: ='Test Case List'!C7 -> TC02.3 | B7: ='Test Case List'!D7 -> Đăng nhập sai email | C7: =Table2[[#This Row],[Module]] -> Auth | D7: =VLOOKUP(A7,'Test Case Coverage Plan'!A8:F32,5,FALSE) -> Yes | E7: Linh Le | F7: Run - Passed
A8: ='Test Case List'!C8 -> TC03.1 | B8: ='Test Case List'!D8 -> Kiểm tra UI form tạo bài viết có đủ các trường thông tin | C8: =Table2[[#This Row],[Module]] -> Article | D8: =VLOOKUP(A8,'Test Case Coverage Plan'!A9:F33,5,FALSE) -> Yes | E8: Linh Le | F8: Run - Passed
A9: ='Test Case List'!C9 -> TC03.2 | B9: ='Test Case List'!D9 -> Kiểm tra khi nhấn nút publish article nhưng bỏ trống các trường bắt buộc | C9: =Table2[[#This Row],[Module]] -> Article | D9: =VLOOKUP(A9,'Test Case Coverage Plan'!A10:F34,5,FALSE) -> Yes | E9: Linh Le | F9: Run - Passed
A10: ='Test Case List'!C10 -> TC03.3 | B10: ='Test Case List'!D10 -> Kiểm tra tạo bài viết với Title đã tồn tại | C10: =Table2[[#This Row],[Module]] -> Article | D10: =VLOOKUP(A10,'Test Case Coverage Plan'!A11:F35,5,FALSE) -> Yes | E10: Linh Le | F10: Run - Failed
A11: ='Test Case List'!C11 -> TC03.4 | B11: ='Test Case List'!D11 -> Kiểm tra số lượng ký tự giới hạn trong các fields | C11: =Table2[[#This Row],[Module]] -> Article | D11: =VLOOKUP(A11,'Test Case Coverage Plan'!A12:F36,5,FALSE) -> Yes | E11: Linh Le | F11: Run - Passed
A12: ='Test Case List'!C12 -> TC03.5 | B12: ='Test Case List'!D12 -> Kiểm tra bài viết hiển thị trên Global Feed, My Article trong User Profile sau khi tạo | C12: =Table2[[#This Row],[Module]] -> Article | D12: =VLOOKUP(A12,'Test Case Coverage Plan'!A13:F37,5,FALSE) -> Yes | E12: Linh Le | F12: Run - Passed
A13: ='Test Case List'!C13 -> TC04.1 | B13: ='Test Case List'!D13 -> Đọc chi tiết bài viết | C13: =Table2[[#This Row],[Module]] -> Article | D13: =VLOOKUP(A13,'Test Case Coverage Plan'!A14:F38,5,FALSE) -> Yes | E13: Linh Le | F13: Run - Passed
... A22: ='Test Case List'!C22 -> TC10.2 | B22: ='Test Case List'!D22 -> Kiểm tra tab Favorited Articles | C22: =Table2[[#This Row],[Module]] -> Profile | D22: =VLOOKUP(A22,'Test Case Coverage Plan'!A23:F47,5,FALSE) -> No | E22: Linh Le | F22: Blocked
A48: Insert Rows Only Above Here | E48: Insert Rows Only Above Here
A50: Warning: Be careful adding/removing rows in the following section - these values are used for data validation
A51: Tester | E51: Test Case Status | H51: Test Iteration Name
A52: Linh Le | E52: N/A | H52: Sprint 2 (Article)
A53: Tester 2 | E53: Not Run
E54: Blocked
E55: In Progress
E56: Run - Passed
E57: Run - Failed

Sheet Sprint 3
A1: Test Case ID | B1: Test Case Name | C1: Module | D1: In This Test Iteration? | E1: Tester | F1: Status | G1: Defects Identified | H1: Blocking Defect ID | I1: Comments
A2: ='Test Case List'!C2 -> TC01.1 | B2: ='Test Case List'!D2 -> Đăng ký hợp lệ | C2: =Table2[[#This Row],[Module]] -> Auth | D2: =VLOOKUP(A2,'Test Case Coverage Plan'!A3:F27,6,FALSE) -> Yes | E2: Linh Le | F2: Run - Passed
A3: ='Test Case List'!C3 -> TC01.2 | B3: ='Test Case List'!D3 -> Đăng ký email trùng với user đã tồn tại trong hệ thống | C3: =Table2[[#This Row],[Module]] -> Auth | D3: =VLOOKUP(A3,'Test Case Coverage Plan'!A4:F28,6,FALSE) -> No | E3: Linh Le | F3: Not Run
A4: ='Test Case List'!C4 -> TC01.3 | B4: ='Test Case List'!D4 -> Đăng ký bỏ trống trường email hoặc trường password | C4: =Table2[[#This Row],[Module]] -> Auth | D4: =VLOOKUP(A4,'Test Case Coverage Plan'!A5:F29,6,FALSE) -> No | E4: Linh Le | F4: Not Run
A5: ='Test Case List'!C5 -> TC02.1 | B5: ='Test Case List'!D5 -> Đăng nhập hợp lệ | C5: =Table2[[#This Row],[Module]] -> Auth | D5: =VLOOKUP(A5,'Test Case Coverage Plan'!A6:F30,6,FALSE) -> Yes | E5: Linh Le | F5: Run - Passed
A6: ='Test Case List'!C6 -> TC02.2 | B6: ='Test Case List'!D6 -> Đăng nhập sai pass | C6: =Table2[[#This Row],[Module]] -> Auth | D6: =VLOOKUP(A6,'Test Case Coverage Plan'!A7:F31,6,FALSE) -> No | E6: Linh Le | F6: Not Run
A7: ='Test Case List'!C7 -> TC02.3 | B7: ='Test Case List'!D7 -> Đăng nhập sai email | C7: =Table2[[#This Row],[Module]] -> Auth | D7: =VLOOKUP(A7,'Test Case Coverage Plan'!A8:F32,6,FALSE) -> No | E7: Linh Le | F7: Not Run
A8: ='Test Case List'!C8 -> TC03.1 | B8: ='Test Case List'!D8 -> Kiểm tra UI form tạo bài viết có đủ các trường thông tin | C8: =Table2[[#This Row],[Module]] -> Article | D8: =VLOOKUP(A8,'Test Case Coverage Plan'!A9:F33,6,FALSE) -> Yes | E8: Linh Le | F8: Run - Passed
A9: ='Test Case List'!C9 -> TC03.2 | B9: ='Test Case List'!D9 -> Kiểm tra khi nhấn nút publish article nhưng bỏ trống các trường bắt buộc | C9: =Table2[[#This Row],[Module]] -> Article | D9: =VLOOKUP(A9,'Test Case Coverage Plan'!A10:F34,6,FALSE) -> Yes | E9: Linh Le | F9: Run - Passed
A10: ='Test Case List'!C10 -> TC03.3 | B10: ='Test Case List'!D10 -> Kiểm tra tạo bài viết với Title đã tồn tại | C10: =Table2[[#This Row],[Module]] -> Article | D10: =VLOOKUP(A10,'Test Case Coverage Plan'!A11:F35,6,FALSE) -> Yes | E10: Linh Le | F10: Run - Passed
A11: ='Test Case List'!C11 -> TC03.4 | B11: ='Test Case List'!D11 -> Kiểm tra số lượng ký tự giới hạn trong các fields | C11: =Table2[[#This Row],[Module]] -> Article | D11: =VLOOKUP(A11,'Test Case Coverage Plan'!A12:F36,6,FALSE) -> Yes | E11: Linh Le | F11: Run - Failed
A12: ='Test Case List'!C12 -> TC03.5 | B12: ='Test Case List'!D12 -> Kiểm tra bài viết hiển thị trên Global Feed, My Article trong User Profile sau khi tạo | C12: =Table2[[#This Row],[Module]] -> Article | D12: =VLOOKUP(A12,'Test Case Coverage Plan'!A13:F37,6,FALSE) -> Yes | E12: Linh Le | F12: Run - Passed
A13: ='Test Case List'!C13 -> TC04.1 | B13: ='Test Case List'!D13 -> Đọc chi tiết bài viết | C13: =Table2[[#This Row],[Module]] -> Article | D13: =VLOOKUP(A13,'Test Case Coverage Plan'!A14:F38,6,FALSE) -> Yes | E13: Linh Le | F13: Run - Passed
... A22: ='Test Case List'!C22 -> TC10.2 | B22: ='Test Case List'!D22 -> Kiểm tra tab Favorited Articles | C22: =Table2[[#This Row],[Module]] -> Profile | D22: =VLOOKUP(A22,'Test Case Coverage Plan'!A23:F47,6,FALSE) -> Yes | E22: Linh Le | F22: Run - Passed
A47: Insert Rows Only Above Here | E47: Insert Rows Only Above Here
A49: Warning: Be careful adding/removing rows in the following section - these values are used for data validation
A50: Tester | E50: Test Case Status | H50: Test Iteration Name
A51: Linh Le | E51: Not Run | H51: Sprint 3 (Social&Profile)
A52: Tester 2 | E52: Blocked
E53: In Progress
E54: Run - Passed
E55: Run - Failed

Sheet Stats
A1: Test Case ID | B1: Test Case Name | C1: Iteration | D1: In This Iteration? | E1: Tester | F1: Status | G1: Module | H1: Priority | I1: Test type
A2: ='Sprint 1'!A2 -> TC01.1 | B2: ='Sprint 1'!B2 -> Đăng ký hợp lệ | C2: ='Sprint 1'!$H$49 -> Sprint 1 (Auth) | D2: ='Sprint 1'!D2 -> Yes | E2: ='Sprint 1'!E2 -> Linh Le | F2: ='Sprint 1'!F2 -> Run - Passed | G2: ='Test Case List'!L2 -> Auth | H2: ='Test Case List'!M2 -> High | I2: ='Test Case List'!N2 -> Functional Testing
A3: ='Sprint 1'!A3 -> TC01.2 | B3: ='Sprint 1'!B3 -> Đăng ký email trùng với user đã tồn tại trong hệ thống | C3: ='Sprint 1'!$H$49 -> Sprint 1 (Auth) | D3: ='Sprint 1'!D3 -> Yes | E3: ='Sprint 1'!E3 -> Linh Le | F3: ='Sprint 1'!F3 -> Run - Passed | G3: ='Test Case List'!L3 -> Auth | H3: ='Test Case List'!M3 -> High | I3: ='Test Case List'!N3 -> Functional Testing
A4: ='Sprint 1'!A4 -> TC01.3 | B4: ='Sprint 1'!B4 -> Đăng ký bỏ trống trường email hoặc trường password | C4: ='Sprint 1'!$H$49 -> Sprint 1 (Auth) | D4: ='Sprint 1'!D4 -> Yes | E4: ='Sprint 1'!E4 -> Linh Le | F4: ='Sprint 1'!F4 -> Run - Passed | G4: ='Test Case List'!L4 -> Auth | H4: ='Test Case List'!M4 -> High | I4: ='Test Case List'!N4 -> Functional Testing
A5: ='Sprint 1'!A5 -> TC02.1 | B5: ='Sprint 1'!B5 -> Đăng nhập hợp lệ | C5: ='Sprint 1'!$H$49 -> Sprint 1 (Auth) | D5: ='Sprint 1'!D5 -> Yes | E5: ='Sprint 1'!E5 -> Linh Le | F5: ='Sprint 1'!F5 -> Run - Passed | G5: ='Test Case List'!L5 -> Auth | H5: ='Test Case List'!M5 -> High | I5: ='Test Case List'!N5 -> Functional Testing
A6: ='Sprint 1'!A6 -> TC02.2 | B6: ='Sprint 1'!B6 -> Đăng nhập sai pass | C6: ='Sprint 1'!$H$49 -> Sprint 1 (Auth) | D6: ='Sprint 1'!D6 -> Yes | E6: ='Sprint 1'!E6 -> Linh Le | F6: ='Sprint 1'!F6 -> Run - Passed | G6: ='Test Case List'!L6 -> Auth | H6: ='Test Case List'!M6 -> High | I6: ='Test Case List'!N6 -> Functional Testing
A7: ='Sprint 1'!A7 -> TC02.3 | B7: ='Sprint 1'!B7 -> Đăng nhập sai email | C7: ='Sprint 1'!$H$49 -> Sprint 1 (Auth) | D7: ='Sprint 1'!D7 -> Yes | E7: ='Sprint 1'!E7 -> Linh Le | F7: ='Sprint 1'!F7 -> Run - Passed | G7: ='Test Case List'!L7 -> Auth | H7: ='Test Case List'!M7 -> High | I7: ='Test Case List'!N7 -> Functional Testing
A8: ='Sprint 1'!A8 -> TC03.1 | B8: ='Sprint 1'!B8 -> Kiểm tra UI form tạo bài viết có đủ các trường thông tin | C8: ='Sprint 1'!$H$49 -> Sprint 1 (Auth) | D8: ='Sprint 1'!D8 -> No | E8: ='Sprint 1'!E8 -> Linh Le | F8: ='Sprint 1'!F8 -> Blocked | G8: ='Test Case List'!L8 -> Article | H8: ='Test Case List'!M8 -> High | I8: ='Test Case List'!N8 -> Functional Testing
A9: ='Sprint 1'!A9 -> TC03.2 | B9: ='Sprint 1'!B9 -> Kiểm tra khi nhấn nút publish article nhưng bỏ trống các trường bắt buộc | C9: ='Sprint 1'!$H$49 -> Sprint 1 (Auth) | D9: ='Sprint 1'!D9 -> No | E9: ='Sprint 1'!E9 -> Linh Le | F9: ='Sprint 1'!F9 -> Blocked | G9: ='Test Case List'!L9 -> Article | H9: ='Test Case List'!M9 -> High | I9: ='Test Case List'!N9 -> Functional Testing
A10: ='Sprint 1'!A10 -> TC03.3 | B10: ='Sprint 1'!B10 -> Kiểm tra tạo bài viết với Title đã tồn tại | C10: ='Sprint 1'!$H$49 -> Sprint 1 (Auth) | D10: ='Sprint 1'!D10 -> No | E10: ='Sprint 1'!E10 -> Linh Le | F10: ='Sprint 1'!F10 -> Blocked | G10: ='Test Case List'!L10 -> Article | H10: ='Test Case List'!M10 -> High | I10: ='Test Case List'!N10 -> Functional Testing
A11: ='Sprint 1'!A11 -> TC03.4 | B11: ='Sprint 1'!B11 -> Kiểm tra số lượng ký tự giới hạn trong các fields | C11: ='Sprint 1'!$H$49 -> Sprint 1 (Auth) | D11: ='Sprint 1'!D11 -> No | E11: ='Sprint 1'!E11 -> Linh Le | F11: ='Sprint 1'!F11 -> Blocked | G11: ='Test Case List'!L11 -> Article | H11: ='Test Case List'!M11 -> High | I11: ='Test Case List'!N11 -> Functional Testing
A12: ='Sprint 1'!A12 -> TC03.5 | B12: ='Sprint 1'!B12 -> Kiểm tra bài viết hiển thị trên Global Feed, My Article trong User Profile sau khi tạo | C12: ='Sprint 1'!$H$49 -> Sprint 1 (Auth) | D12: ='Sprint 1'!D12 -> No | E12: ='Sprint 1'!E12 -> Linh Le | F12: ='Sprint 1'!F12 -> Blocked | G12: ='Test Case List'!L12 -> Article | H12: ='Test Case List'!M12 -> High | I12: ='Test Case List'!N12 -> Functional Testing
A13: ='Sprint 1'!A13 -> TC04.1 | B13: ='Sprint 1'!B13 -> Đọc chi tiết bài viết | C13: ='Sprint 1'!$H$49 -> Sprint 1 (Auth) | D13: ='Sprint 1'!D13 -> No | E13: ='Sprint 1'!E13 -> Linh Le | F13: ='Sprint 1'!F13 -> Blocked | G13: ='Test Case List'!L13 -> Article | H13: ='Test Case List'!M13 -> High | I13: ='Test Case List'!N13 -> Functional Testing
... A22: ='Sprint 1'!A22 -> TC10.2 | B22: ='Sprint 1'!B22 -> Kiểm tra tab Favorited Articles | C22: ='Sprint 1'!$H$49 -> Sprint 1 (Auth) | D22: ='Sprint 1'!D22 -> No | E22: ='Sprint 1'!E22 -> Linh Le | F22: ='Sprint 1'!F22 -> Blocked | G22: ='Test Case List'!L22 -> Profile | H22: ='Test Case List'!M22 -> High | I22: ='Test Case List'!N22 -> Functional Testing
A23: ='Sprint 2'!A2 -> TC01.1 | B23: ='Sprint 2'!B2 -> Đăng ký hợp lệ | C23: ='Sprint 2'!$H$52 -> Sprint 2 (Article) | D23: ='Sprint 2'!D2 -> No | E23: ='Sprint 2'!E2 -> Linh Le | F23: ='Sprint 2'!F2 -> Not Run | G23: ='Test Case List'!L2 -> Auth | H23: ='Test Case List'!M2 -> High | I23: ='Test Case List'!N2 -> Functional Testing
A24: ='Sprint 2'!A3 -> TC01.2 | B24: ='Sprint 2'!B3 -> Đăng ký email trùng với user đã tồn tại trong hệ thống | C24: ='Sprint 2'!$H$52 -> Sprint 2 (Article) | D24: ='Sprint 2'!D3 -> No | E24: ='Sprint 2'!E3 -> Linh Le | F24: ='Sprint 2'!F3 -> Not Run | G24: ='Test Case List'!L3 -> Auth | H24: ='Test Case List'!M3 -> High | I24: ='Test Case List'!N3 -> Functional Testing
A25: ='Sprint 2'!A4 -> TC01.3 | B25: ='Sprint 2'!B4 -> Đăng ký bỏ trống trường email hoặc trường password | C25: ='Sprint 2'!$H$52 -> Sprint 2 (Article) | D25: ='Sprint 2'!D4 -> No | E25: ='Sprint 2'!E4 -> Linh Le | F25: ='Sprint 2'!F4 -> Not Run | G25: ='Test Case List'!L4 -> Auth | H25: ='Test Case List'!M4 -> High | I25: ='Test Case List'!N4 -> Functional Testing
A26: ='Sprint 2'!A5 -> TC02.1 | B26: ='Sprint 2'!B5 -> Đăng nhập hợp lệ | C26: ='Sprint 2'!$H$52 -> Sprint 2 (Article) | D26: ='Sprint 2'!D5 -> Yes | E26: ='Sprint 2'!E5 -> Linh Le | F26: ='Sprint 2'!F5 -> Run - Passed | G26: ='Test Case List'!L5 -> Auth | H26: ='Test Case List'!M5 -> High | I26: ='Test Case List'!N5 -> Functional Testing
A27: ='Sprint 2'!A6 -> TC02.2 | B27: ='Sprint 2'!B6 -> Đăng nhập sai pass | C27: ='Sprint 2'!$H$52 -> Sprint 2 (Article) | D27: ='Sprint 2'!D6 -> Yes | E27: ='Sprint 2'!E6 -> Linh Le | F27: ='Sprint 2'!F6 -> Run - Passed | G27: ='Test Case List'!L6 -> Auth | H27: ='Test Case List'!M6 -> High | I27: ='Test Case List'!N6 -> Functional Testing
A28: ='Sprint 2'!A7 -> TC02.3 | B28: ='Sprint 2'!B7 -> Đăng nhập sai email | C28: ='Sprint 2'!$H$52 -> Sprint 2 (Article) | D28: ='Sprint 2'!D7 -> Yes | E28: ='Sprint 2'!E7 -> Linh Le | F28: ='Sprint 2'!F7 -> Run - Passed | G28: ='Test Case List'!L7 -> Auth | H28: ='Test Case List'!M7 -> High | I28: ='Test Case List'!N7 -> Functional Testing
A29: ='Sprint 2'!A8 -> TC03.1 | B29: ='Sprint 2'!B8 -> Kiểm tra UI form tạo bài viết có đủ các trường thông tin | C29: ='Sprint 2'!$H$52 -> Sprint 2 (Article) | D29: ='Sprint 2'!D8 -> Yes | E29: ='Sprint 2'!E8 -> Linh Le | F29: ='Sprint 2'!F8 -> Run - Passed | G29: ='Test Case List'!L8 -> Article | H29: ='Test Case List'!M8 -> High | I29: ='Test Case List'!N8 -> Functional Testing
A30: ='Sprint 2'!A9 -> TC03.2 | B30: ='Sprint 2'!B9 -> Kiểm tra khi nhấn nút publish article nhưng bỏ trống các trường bắt buộc | C30: ='Sprint 2'!$H$52 -> Sprint 2 (Article) | D30: ='Sprint 2'!D9 -> Yes | E30: ='Sprint 2'!E9 -> Linh Le | F30: ='Sprint 2'!F9 -> Run - Passed | G30: ='Test Case List'!L9 -> Article | H30: ='Test Case List'!M9 -> High | I30: ='Test Case List'!N9 -> Functional Testing
A31: ='Sprint 2'!A10 -> TC03.3 | B31: ='Sprint 2'!B10 -> Kiểm tra tạo bài viết với Title đã tồn tại | C31: ='Sprint 2'!$H$52 -> Sprint 2 (Article) | D31: ='Sprint 2'!D10 -> Yes | E31: ='Sprint 2'!E10 -> Linh Le | F31: ='Sprint 2'!F10 -> Run - Failed | G31: ='Test Case List'!L10 -> Article | H31: ='Test Case List'!M10 -> High | I31: ='Test Case List'!N10 -> Functional Testing
A32: ='Sprint 2'!A11 -> TC03.4 | B32: ='Sprint 2'!B11 -> Kiểm tra số lượng ký tự giới hạn trong các fields | C32: ='Sprint 2'!$H$52 -> Sprint 2 (Article) | D32: ='Sprint 2'!D11 -> Yes | E32: ='Sprint 2'!E11 -> Linh Le | F32: ='Sprint 2'!F11 -> Run - Passed | G32: ='Test Case List'!L11 -> Article | H32: ='Test Case List'!M11 -> High | I32: ='Test Case List'!N11 -> Functional Testing
A33: ='Sprint 2'!A12 -> TC03.5 | B33: ='Sprint 2'!B12 -> Kiểm tra bài viết hiển thị trên Global Feed, My Article trong User Profile sau khi tạo | C33: ='Sprint 2'!$H$52 -> Sprint 2 (Article) | D33: ='Sprint 2'!D12 -> Yes | E33: ='Sprint 2'!E12 -> Linh Le | F33: ='Sprint 2'!F12 -> Run - Passed | G33: ='Test Case List'!L12 -> Article | H33: ='Test Case List'!M12 -> High | I33: ='Test Case List'!N12 -> Functional Testing
A34: ='Sprint 2'!A13 -> TC04.1 | B34: ='Sprint 2'!B13 -> Đọc chi tiết bài viết | C34: ='Sprint 2'!$H$52 -> Sprint 2 (Article) | D34: ='Sprint 2'!D13 -> Yes | E34: ='Sprint 2'!E13 -> Linh Le | F34: ='Sprint 2'!F13 -> Run - Passed | G34: ='Test Case List'!L13 -> Article | H34: ='Test Case List'!M13 -> High | I34: ='Test Case List'!N13 -> Functional Testing
... A43: ='Sprint 2'!A22 -> TC10.2 | B43: ='Sprint 2'!B22 -> Kiểm tra tab Favorited Articles | C43: ='Sprint 2'!$H$52 -> Sprint 2 (Article) | D43: ='Sprint 2'!D22 -> No | E43: ='Sprint 2'!E22 -> Linh Le | F43: ='Sprint 2'!F22 -> Blocked | G43: ='Test Case List'!L22 -> Profile | H43: ='Test Case List'!M22 -> High | I43: ='Test Case List'!N22 -> Functional Testing
A44: ='Sprint 3'!A2 -> TC01.1 | B44: ='Sprint 3'!B2 -> Đăng ký hợp lệ | C44: ='Sprint 3'!$H$51 -> Sprint 3 (Social&Profile) | D44: ='Sprint 3'!D2 -> Yes | E44: ='Sprint 3'!E2 -> Linh Le | F44: ='Sprint 3'!F2 -> Run - Passed | G44: ='Test Case List'!L2 -> Auth | H44: ='Test Case List'!M2 -> High | I44: ='Test Case List'!N2 -> Functional Testing
A45: ='Sprint 3'!A3 -> TC01.2 | B45: ='Sprint 3'!B3 -> Đăng ký email trùng với user đã tồn tại trong hệ thống | C45: ='Sprint 3'!$H$51 -> Sprint 3 (Social&Profile) | D45: ='Sprint 3'!D3 -> No | E45: ='Sprint 3'!E3 -> Linh Le | F45: ='Sprint 3'!F3 -> Not Run | G45: ='Test Case List'!L3 -> Auth | H45: ='Test Case List'!M3 -> High | I45: ='Test Case List'!N3 -> Functional Testing
A46: ='Sprint 3'!A4 -> TC01.3 | B46: ='Sprint 3'!B4 -> Đăng ký bỏ trống trường email hoặc trường password | C46: ='Sprint 3'!$H$51 -> Sprint 3 (Social&Profile) | D46: ='Sprint 3'!D4 -> No | E46: ='Sprint 3'!E4 -> Linh Le | F46: ='Sprint 3'!F4 -> Not Run | G46: ='Test Case List'!L4 -> Auth | H46: ='Test Case List'!M4 -> High | I46: ='Test Case List'!N4 -> Functional Testing
A47: ='Sprint 3'!A5 -> TC02.1 | B47: ='Sprint 3'!B5 -> Đăng nhập hợp lệ | C47: ='Sprint 3'!$H$51 -> Sprint 3 (Social&Profile) | D47: ='Sprint 3'!D5 -> Yes | E47: ='Sprint 3'!E5 -> Linh Le | F47: ='Sprint 3'!F5 -> Run - Passed | G47: ='Test Case List'!L5 -> Auth | H47: ='Test Case List'!M5 -> High | I47: ='Test Case List'!N5 -> Functional Testing
A48: ='Sprint 3'!A6 -> TC02.2 | B48: ='Sprint 3'!B6 -> Đăng nhập sai pass | C48: ='Sprint 3'!$H$51 -> Sprint 3 (Social&Profile) | D48: ='Sprint 3'!D6 -> No | E48: ='Sprint 3'!E6 -> Linh Le | F48: ='Sprint 3'!F6 -> Not Run | G48: ='Test Case List'!L6 -> Auth | H48: ='Test Case List'!M6 -> High | I48: ='Test Case List'!N6 -> Functional Testing
A49: ='Sprint 3'!A7 -> TC02.3 | B49: ='Sprint 3'!B7 -> Đăng nhập sai email | C49: ='Sprint 3'!$H$51 -> Sprint 3 (Social&Profile) | D49: ='Sprint 3'!D7 -> No | E49: ='Sprint 3'!E7 -> Linh Le | F49: ='Sprint 3'!F7 -> Not Run | G49: ='Test Case List'!L7 -> Auth | H49: ='Test Case List'!M7 -> High | I49: ='Test Case List'!N7 -> Functional Testing
A50: ='Sprint 3'!A8 -> TC03.1 | B50: ='Sprint 3'!B8 -> Kiểm tra UI form tạo bài viết có đủ các trường thông tin | C50: ='Sprint 3'!$H$51 -> Sprint 3 (Social&Profile) | D50: ='Sprint 3'!D8 -> Yes | E50: ='Sprint 3'!E8 -> Linh Le | F50: ='Sprint 3'!F8 -> Run - Passed | G50: ='Test Case List'!L8 -> Article | H50: ='Test Case List'!M8 -> High | I50: ='Test Case List'!N8 -> Functional Testing
A51: ='Sprint 3'!A9 -> TC03.2 | B51: ='Sprint 3'!B9 -> Kiểm tra khi nhấn nút publish article nhưng bỏ trống các trường bắt buộc | C51: ='Sprint 3'!$H$51 -> Sprint 3 (Social&Profile) | D51: ='Sprint 3'!D9 -> Yes | E51: ='Sprint 3'!E9 -> Linh Le | F51: ='Sprint 3'!F9 -> Run - Passed | G51: ='Test Case List'!L9 -> Article | H51: ='Test Case List'!M9 -> High | I51: ='Test Case List'!N9 -> Functional Testing
A52: ='Sprint 3'!A10 -> TC03.3 | B52: ='Sprint 3'!B10 -> Kiểm tra tạo bài viết với Title đã tồn tại | C52: ='Sprint 3'!$H$51 -> Sprint 3 (Social&Profile) | D52: ='Sprint 3'!D10 -> Yes | E52: ='Sprint 3'!E10 -> Linh Le | F52: ='Sprint 3'!F10 -> Run - Passed | G52: ='Test Case List'!L10 -> Article | H52: ='Test Case List'!M10 -> High | I52: ='Test Case List'!N10 -> Functional Testing
A53: ='Sprint 3'!A11 -> TC03.4 | B53: ='Sprint 3'!B11 -> Kiểm tra số lượng ký tự giới hạn trong các fields | C53: ='Sprint 3'!$H$51 -> Sprint 3 (Social&Profile) | D53: ='Sprint 3'!D11 -> Yes | E53: ='Sprint 3'!E11 -> Linh Le | F53: ='Sprint 3'!F11 -> Run - Failed | G53: ='Test Case List'!L11 -> Article | H53: ='Test Case List'!M11 -> High | I53: ='Test Case List'!N11 -> Functional Testing
A54: ='Sprint 3'!A12 -> TC03.5 | B54: ='Sprint 3'!B12 -> Kiểm tra bài viết hiển thị trên Global Feed, My Article trong User Profile sau khi tạo | C54: ='Sprint 3'!$H$51 -> Sprint 3 (Social&Profile) | D54: ='Sprint 3'!D12 -> Yes | E54: ='Sprint 3'!E12 -> Linh Le | F54: ='Sprint 3'!F12 -> Run - Passed | G54: ='Test Case List'!L12 -> Article | H54: ='Test Case List'!M12 -> High | I54: ='Test Case List'!N12 -> Functional Testing
A55: ='Sprint 3'!A13 -> TC04.1 | B55: ='Sprint 3'!B13 -> Đọc chi tiết bài viết | C55: ='Sprint 3'!$H$51 -> Sprint 3 (Social&Profile) | D55: ='Sprint 3'!D13 -> Yes | E55: ='Sprint 3'!E13 -> Linh Le | F55: ='Sprint 3'!F13 -> Run - Passed | G55: ='Test Case List'!L13 -> Article | H55: ='Test Case List'!M13 -> High | I55: ='Test Case List'!N13 -> Functional Testing
... A64: ='Sprint 3'!A22 -> TC10.2 | B64: ='Sprint 3'!B22 -> Kiểm tra tab Favorited Articles | C64: ='Sprint 3'!$H$51 -> Sprint 3 (Social&Profile) | D64: ='Sprint 3'!D22 -> Yes | E64: ='Sprint 3'!E22 -> Linh Le | F64: ='Sprint 3'!F22 -> Run - Passed | G64: ='Test Case List'!L22 -> Profile | H64: ='Test Case List'!M22 -> High | I64: ='Test Case List'!N22 -> Functional Testing
...

Sheet Pivot
L3: Module Status by Iteration
A4: Status by Iteration | L4: Iteration | M4: (All)
A5: In This Iteration? | B5: (All) | L5: In This Iteration? | M5: (All)
A7: Count of Test Case ID | B7: Iteration | L7: Count of Test Case ID | M7: Status
A8: Status | B8: Sprint 1 (Auth) | C8: Sprint 2 (Article) | D8: Sprint 3 (Social&Profile) | E8: (blank) | F8: Grand Total | L8: Module | M8: Blocked | N8: Not Run | O8: Run - Passed | P8: Run - Failed | Q8: (blank) | R8: Grand Total
A9: Blocked | B9: 15 | C9: 6 | F9: 21 | L9: Auth | N9: 7 | O9: 11 | R9: 18
A10: Not Run | C10: 3 | D10: 4 | F10: 7 | L10: Article | M10: 9 | O10: 16 | P10: 2 | R10: 27
A11: Run - Passed | B11: 6 | C11: 11 | D11: 16 | F11: 33 | L11: Social | M11: 8 | O11: 4 | R11: 12
A12: Run - Failed | C12: 1 | D12: 1 | F12: 2 | L12: Profile | M12: 4 | O12: 2 | R12: 6
A13: (blank) | L13: (blank)
A14: Grand Total | B14: 21 | C14: 21 | D14: 21 | F14: 63 | L14: Grand Total | M14: 21 | N14: 7 | O14: 33 | P14: 2 | R14: 63
A16: Test Case Status by Iteration
A17: Iteration | B17: (All)
A18: In This Iteration? | B18: (All)
A20: Count of Test Case ID | B20: Status
A21: Test Case ID | B21: Blocked | C21: Not Run | D21: Run - Passed | E21: Run - Failed | F21: (blank) | G21: Grand Total | L21: Test Type Status by Iteration
A22: TC10.1 | B22: 2 | D22: 1 | G22: 3 | L22: Iteration | M22: (All)
A23: TC10.2 | B23: 2 | D23: 1 | G23: 3 | L23: In This Iteration? | M23: (All)
A24: TC01.1 | C24: 1 | D24: 2 | G24: 3
A25: TC01.2 | C25: 2 | D25: 1 | G25: 3 | L25: Count of Test Case ID | M25: Status
A26: TC01.3 | C26: 2 | D26: 1 | G26: 3 | L26: Test type | M26: Blocked | N26: Not Run | O26: Run - Passed | P26: Run - Failed | Q26: (blank) | R26: Grand Total
A27: TC02.1 | D27: 3 | G27: 3 | L27: Functional Testing | M27: 21 | N27: 7 | O27: 33 | P27: 2 | R27: 63
A28: TC02.2 | C28: 1 | D28: 2 | G28: 3 | L28: (blank)
A29: TC02.3 | C29: 1 | D29: 2 | G29: 3 | L29: Grand Total | M29: 21 | N29: 7 | O29: 33 | P29: 2 | R29: 63
A30: TC03.1 | B30: 1 | D30: 2 | G30: 3
A31: TC03.2 | B31: 1 | D31: 2 | G31: 3
A32: TC03.3 | B32: 1 | D32: 1 | E32: 1 | G32: 3
A33: TC03.4 | B33: 1 | D33: 1 | E33: 1 | G33: 3
A34: TC03.5 | B34: 1 | D34: 2 | G34: 3
A35: TC04.1 | B35: 1 | D35: 2 | G35: 3
A36: TC05.1 | B36: 1 | D36: 2 | G36: 3
A37: TC05.2 | B37: 1 | D37: 2 | G37: 3
A38: TC06.1 | B38: 1 | D38: 2 | G38: 3
A39: TC07.1 | B39: 2 | D39: 1 | G39: 3
A40: TC07.2 | B40: 2 | D40: 1 | G40: 3
A41: TC08.1 | B41: 2 | D41: 1 | G41: 3
A42: TC09.1 | B42: 2 | D42: 1 | G42: 3
A43: (blank)
A44: Grand Total | B44: 21 | C44: 7 | D44: 33 | E44: 2 | G44: 63

Sheet Test Case Status by Iteration

Sheet Regression Testing
A1: Scenario ID | B1: Scenario | C1: Test Case ID | D1: Test Case Name | E1: Test Case Description | F1: Expected Result | G1: Status | H1: Module
A2: =Table2[[#This Row],[Scenario ID]] -> TS1 | B2: =Table2[[#This Row],[Scenario]] -> Đăng ký | C2: =Table2[[#This Row],[Test Case ID]] -> TC01.1 | D2: =Table2[[#This Row],[Test Case Name]] -> Đăng ký hợp lệ | E2: =Table2[[#This Row],[Test Case Description]] -> B1: Điền đúng email hợp lệ B2: Điền đúng password theo yêu cầu B3: Điền Tên của người dùng B4: Nhấn nút đăng ký | F2: =Table2[[#This Row],[Expected Result]] -> Đăng ký thành công kèm thông báo | G2: Passed | H2: =Table2[[#This Row],[Module]] -> Auth
A3: =Table2[[#This Row],[Scenario ID]] -> TS1 | B3: =Table2[[#This Row],[Scenario]] -> Đăng ký | C3: =Table2[[#This Row],[Test Case ID]] -> TC01.2 | D3: =Table2[[#This Row],[Test Case Name]] -> Đăng ký email trùng với user đã tồn tại trong hệ thống | E3: =Table2[[#This Row],[Test Case Description]] -> B1: Tạo sẵn 1 user với email trong hệ thống B2: Đăng ký thêm với cùng email đó B3: Nhấn nút đăng ký | F3: =Table2[[#This Row],[Expected Result]] -> Hệ thống báo lỗi email đã được sử dụng | G3: Passed | H3: =Table2[[#This Row],[Module]] -> Auth
A4: =Table2[[#This Row],[Scenario ID]] -> TS1 | B4: =Table2[[#This Row],[Scenario]] -> Đăng ký | C4: =Table2[[#This Row],[Test Case ID]] -> TC01.3 | D4: =Table2[[#This Row],[Test Case Name]] -> Đăng ký bỏ trống trường email hoặc trường password | E4: =Table2[[#This Row],[Test Case Description]] -> B1: Điền Tên người dùng B2: bỏ trống email hoặc password B3: nhấn nút đăng ký | F4: =Table2[[#This Row],[Expected Result]] -> Hệ thống báo lỗi cần nhập email/password | G4: Passed | H4: =Table2[[#This Row],[Module]] -> Auth
A5: =Table2[[#This Row],[Scenario ID]] -> TS2 | B5: =Table2[[#This Row],[Scenario]] -> Đăng nhập | C5: =Table2[[#This Row],[Test Case ID]] -> TC02.1 | D5: =Table2[[#This Row],[Test Case Name]] -> Đăng nhập hợp lệ | E5: =Table2[[#This Row],[Test Case Description]] -> B1: Điền thông tin email B2: Điền thông tin password B3: Nhấn nút đăng nhập | F5: =Table2[[#This Row],[Expected Result]] -> Hệ thống thông báo đăng nhập thành công và điều hướng đến trang chủ | G5: Passed | H5: =Table2[[#This Row],[Module]] -> Auth
A6: =Table2[[#This Row],[Scenario ID]] -> TS2 | B6: =Table2[[#This Row],[Scenario]] -> Đăng nhập | C6: =Table2[[#This Row],[Test Case ID]] -> TC02.2 | D6: =Table2[[#This Row],[Test Case Name]] -> Đăng nhập sai pass | E6: =Table2[[#This Row],[Test Case Description]] -> B1: Điền thông tin email B2: Điền thông tin password sai B3: Nhấn nút đăng nhập | F6: =Table2[[#This Row],[Expected Result]] -> Hệ thống báo lỗi mật khẩu không đúng | G6: Passed | H6: =Table2[[#This Row],[Module]] -> Auth
A7: =Table2[[#This Row],[Scenario ID]] -> TS2 | B7: =Table2[[#This Row],[Scenario]] -> Đăng nhập | C7: =Table2[[#This Row],[Test Case ID]] -> TC02.3 | D7: =Table2[[#This Row],[Test Case Name]] -> Đăng nhập sai email | E7: =Table2[[#This Row],[Test Case Description]] -> B1: Điền thông tin email sai B2: Điền thông tin password đúng B3: Nhấn nút đăng nhập | F7: =Table2[[#This Row],[Expected Result]] -> Hệ thống báo lỗi email không đúng | G7: Passed | H7: =Table2[[#This Row],[Module]] -> Auth
A8: =Table2[[#This Row],[Scenario ID]] -> TS3 | B8: =Table2[[#This Row],[Scenario]] -> Tạo bài viết | C8: =Table2[[#This Row],[Test Case ID]] -> TC03.1 | D8: =Table2[[#This Row],[Test Case Name]] -> Kiểm tra UI form tạo bài viết có đủ các trường thông tin | E8: =Table2[[#This Row],[Test Case Description]] -> B1: Nhấn nút New Article B2: Xác nhận đủ các field (Title, About, Body, Tags) | F8: =Table2[[#This Row],[Expected Result]] -> Có đủ các field (Title, About, Body, Tags) | G8: Passed | H8: =Table2[[#This Row],[Module]] -> Article
A9: =Table2[[#This Row],[Scenario ID]] -> TS3 | B9: =Table2[[#This Row],[Scenario]] -> Tạo bài viết | C9: =Table2[[#This Row],[Test Case ID]] -> TC03.2 | D9: =Table2[[#This Row],[Test Case Name]] -> Kiểm tra khi nhấn nút publish article nhưng bỏ trống các trường bắt buộc | E9: =Table2[[#This Row],[Test Case Description]] -> B1: Nhấn nút New Article B2: bỏ trống 1 trong các fields (Title, About, Body) B3: nhấn nút publish article | F9: =Table2[[#This Row],[Expected Result]] -> Hệ thống báo lỗi cần điền các fields (Title, About, Body) | G9: Passed | H9: =Table2[[#This Row],[Module]] -> Article
A10: =Table2[[#This Row],[Scenario ID]] -> TS3 | B10: =Table2[[#This Row],[Scenario]] -> Tạo bài viết | C10: =Table2[[#This Row],[Test Case ID]] -> TC03.3 | D10: =Table2[[#This Row],[Test Case Name]] -> Kiểm tra tạo bài viết với Title đã tồn tại | E10: =Table2[[#This Row],[Test Case Description]] -> B1: Nhấn nút New Article B2: điền đủ các fields (Title, About, Body, Tags) B3: nhấn nút publish article B4: Nhấn nút New Article B5: điền đủ các fields (Title, About, Body, Tags) nhưng với title name trùng với B2 B6: nhấn nút publish article | F10: =Table2[[#This Row],[Expected Result]] -> Hệ thống cho phép tạo thành công bình thường | G10: Failed | H10: =Table2[[#This Row],[Module]] -> Article
A11: =Table2[[#This Row],[Scenario ID]] -> TS3 | B11: =Table2[[#This Row],[Scenario]] -> Tạo bài viết | C11: =Table2[[#This Row],[Test Case ID]] -> TC03.4 | D11: =Table2[[#This Row],[Test Case Name]] -> Kiểm tra số lượng ký tự giới hạn trong các fields | E11: =Table2[[#This Row],[Test Case Description]] -> Boundary testing | F11: =Table2[[#This Row],[Expected Result]] -> Giới hạn text | G11: Failed | H11: =Table2[[#This Row],[Module]] -> Article
A12: =Table2[[#This Row],[Scenario ID]] -> TS3 | B12: =Table2[[#This Row],[Scenario]] -> Tạo bài viết | C12: =Table2[[#This Row],[Test Case ID]] -> TC03.5 | D12: =Table2[[#This Row],[Test Case Name]] -> Kiểm tra bài viết hiển thị trên Global Feed, My Article trong User Profile sau khi tạo | E12: =Table2[[#This Row],[Test Case Description]] -> B1: tạo bài viết B2: truy cập các trang Global Feed, My Article trong User Profile và kiểm tra bài viết | F12: =Table2[[#This Row],[Expected Result]] -> Bài viết mới tạo hiện thị trên đầu ở các trang Global Feed, My Article trong User Profile | G12: Passed | H12: =Table2[[#This Row],[Module]] -> Article
A13: =Table2[[#This Row],[Scenario ID]] -> TS4 | B13: =Table2[[#This Row],[Scenario]] -> Đọc bài viết | C13: =Table2[[#This Row],[Test Case ID]] -> TC04.1 | D13: =Table2[[#This Row],[Test Case Name]] -> Đọc chi tiết bài viết | E13: =Table2[[#This Row],[Test Case Description]] -> B1: Nhấn vào tiêu đề bài viết hoặc nhấn vào nút View more B2: Kiểm tra điều hướng của hệ thống và nội dung văn bản khi xem | F13: =Table2[[#This Row],[Expected Result]] -> Hệ thống điều hướng qua trang xem chi tiết bài viết Văn bản được render ngay ngăn, không bị tràn hay vỡ layout | G13: Passed | H13: =Table2[[#This Row],[Module]] -> Article
... A16: =Table2[[#This Row],[Scenario ID]] -> TS6 | B16: =Table2[[#This Row],[Scenario]] -> Xóa bài viết | C16: =Table2[[#This Row],[Test Case ID]] -> TC06.1 | D16: =Table2[[#This Row],[Test Case Name]] -> Xóa bài viết thành công | E16: =Table2[[#This Row],[Test Case Description]] -> B1: Truy câp trang chi tiết bài viết của 1 bài B2: nhấn nút delete article B3: nhấn nút xác nhận khi hệ thống hiển thị pop-up xác nhận xóa | F16: =Table2[[#This Row],[Expected Result]] -> Bài viết bị xóa khỏi UI và DB và không hiển thị bài viết này ở các trang tương ứng Global Feed, My Article trong User Profile | G16: Passed | H16: =Table2[[#This Row],[Module]] -> Article
A17: =Table2[[#This Row],[Scenario ID]] -> TS7 | B17: =Table2[[#This Row],[Scenario]] -> Bình luận | C17: =Table2[[#This Row],[Test Case ID]] -> TC07.1 | D17: =Table2[[#This Row],[Test Case Name]] -> Thêm bình luận mới thành công | E17: =Table2[[#This Row],[Test Case Description]] -> B1: Truy câp trang chi tiết bài viết của 1 bài B2: nhập bình luận và nhấn nút Post comment B3: kiểm tra bình luận hiển thị trong bài viết | F17: =Table2[[#This Row],[Expected Result]] -> Bình luận hiển thị trong bài viết kèm tên người bình luận và thời gian bình luận Bình luận mới sẽ hiển thị lên đầu | G17: Passed | H17: =Table2[[#This Row],[Module]] -> Social | J17: Column1 | K17: Column2
A18: =Table2[[#This Row],[Scenario ID]] -> TS7 | B18: =Table2[[#This Row],[Scenario]] -> Bình luận | C18: =Table2[[#This Row],[Test Case ID]] -> TC07.2 | D18: =Table2[[#This Row],[Test Case Name]] -> Xóa bình luận | E18: =Table2[[#This Row],[Test Case Description]] -> B1: Truy câp trang chi tiết bài viết của 1 bài viết với điều kiện bài viết đó đã có nhiều bình luận từ chính mình và từ người khác B2: kiểm tra nút xóa ở cạnh mỗi bình luận B3: kiểm tra sau khi nhấn nút xóa | F18: =Table2[[#This Row],[Expected Result]] -> nút xóa chỉ hiển thị cạnh bình luận của chính mình khi nhấn nút xóa thì bình luận biến mất | G18: Passed | H18: =Table2[[#This Row],[Module]] -> Social | J18: Test Execution | K18: =COUNTA(Table3[Status])/COUNTA(Table3[Scenario ID])*100 -> 100
A19: =Table2[[#This Row],[Scenario ID]] -> TS8 | B19: =Table2[[#This Row],[Scenario]] -> Danh sách Yêu thích | C19: =Table2[[#This Row],[Test Case ID]] -> TC08.1 | D19: =Table2[[#This Row],[Test Case Name]] -> Thả tim và bỏ thả tym bài viết | E19: =Table2[[#This Row],[Test Case Description]] -> B1: Thả tym và bài viết bất kì ở trang Global Feed B2: Kiểm tra bài viết này ở các trang còn lại xem biểu tượng tym có hiển thị đã tick tương ứng không B3: bỏ thả tym cho bài viết B4: Kiểm tra bài viết này ở các trang còn lại xem biểu tượng tym có bị untick tương ứng không | F19: =Table2[[#This Row],[Expected Result]] -> Khi thả tym, biểu tượng tym sáng màu xanh lá cây, còn khi bỏ thay tym thì biểu tượng tym hiển thị màu trắng | G19: Passed | H19: =Table2[[#This Row],[Module]] -> Social | J19: Pass Rate | K19: =COUNTIF(Table3[Status],"Passed")/COUNTA(Table3[Status])*100 -> 90.47619
A20: =Table2[[#This Row],[Scenario ID]] -> TS9 | B20: =Table2[[#This Row],[Scenario]] -> Theo dõi tác giả yêu thích | C20: =Table2[[#This Row],[Test Case ID]] -> TC09.1 | D20: =Table2[[#This Row],[Test Case Name]] -> Theo dõi tác giả có bài viết hay | E20: =Table2[[#This Row],[Test Case Description]] -> B1: xem chi tiết bài viết của 1 tác giả bất kì B2: nhấn nút theo dõi tác giả B3: Kiểm tra trạng thái nút và trang Your Feed | F20: =Table2[[#This Row],[Expected Result]] -> Nút chuyển qua trạng thái đã follow và trang Your Feed chỉ hiển thị các bài viết của tác giả vừa theo dõi | G20: Passed | H20: =Table2[[#This Row],[Module]] -> Social
A21: =Table2[[#This Row],[Scenario ID]] -> TS10 | B21: =Table2[[#This Row],[Scenario]] -> Hồ sơ cá nhân | C21: =Table2[[#This Row],[Test Case ID]] -> TC10.1 | D21: =Table2[[#This Row],[Test Case Name]] -> Kiểm tra tab My Articles | E21: =Table2[[#This Row],[Test Case Description]] -> B1: Truy cập trang User profile B2: kiểm tra tab My Articles | F21: =Table2[[#This Row],[Expected Result]] -> Chỉ hiển thị bài viết của chính mình, bài mới nhất sẽ hiển thị lên đầu | G21: Passed | H21: =Table2[[#This Row],[Module]] -> Profile
A22: =Table2[[#This Row],[Scenario ID]] -> TS10 | B22: =Table2[[#This Row],[Scenario]] -> Hồ sơ cá nhân | C22: =Table2[[#This Row],[Test Case ID]] -> TC10.2 | D22: =Table2[[#This Row],[Test Case Name]] -> Kiểm tra tab Favorited Articles | E22: =Table2[[#This Row],[Test Case Description]] -> B1: Truy cập trang User profile B2: kiểm tra tab Favorited Articles | F22: =Table2[[#This Row],[Expected Result]] -> hiển thị bài viết mà mình đã thả tym, bài mới nhất sẽ hiển thị lên đầu | G22: Passed | H22: =Table2[[#This Row],[Module]] -> Profile
D26: Count of Test Case ID | E26: Module
D27: Status | E27: Article | F27: Auth | G27: Profile | H27: Social | I27: Grand Total
D28: Passed | E28: 7 | F28: 6 | G28: 2 | H28: 4 | I28: 19
D29: Failed | E29: 2 | I29: 2
D30: Grand Total | E30: 9 | F30: 6 | G30: 2 | H30: 4 | I30: 21
